Workbook

Sheet מפת החלטות מאסטר
A1: Master Decision Matrix — מפת החלטות תפעוליות לבניין (KEEP / SKIP / INSPECT / ACT)
A2: מקור: תוכנית האחזקה המונעת (230 משימות, 12 מערכות) — נבחרו 36 המשימות בעלות פוטנציאל ההשפעה הגבוה ביותר לשלב 1. כל שעות/זמן הן הערכות ראשוניות (MVP) לאימות מול נתוני אמת בפיילוט.
A3: # | B3: מערכת | C3: ציוד / רכיב | D3: משימה (מקור: תוכנית האחזקה) | E3: תדירות נוכחית | F3: סיווג אסטרטגי | G3: מופעים לשנה (היום) | H3: מה נבדק בפועל (תמצית) | I3: מקור החובה (Compliance) | J3: נתון קיים בבקר/BMS? | K3: חיישן IoT נדרש | L3: בדיקה פיזית חובה עפ"י דין/תקן? | M3: ניתן למעבר לניהול מבוסס חריגות? | N3: החלטת ברירת מחדל | O3: תנאי SKIP | P3: תנאי INSPECT | Q3: תנאי ACT | R3: זמן ביצוע היום (דק') | S3: שעות/שנה - היום | T3: מופעים חזויים לשנה | U3: זמן ביצוע חזוי (דק') | V3: שעות/שנה - חזוי | W3: חיסכון שעות/שנה | X3: % חיסכון | Y3: הערות / הנחות
A4: 1 | B4: מיזוג אוויר | C4: צ'ילר | D4: בדיקת צ'ילרים | E4: יומי | F4: A — נתון קיים בבקר (אוטומציה מיידית) | G4: 365 | H4: רישום ידני של לחץ יניקה/דחיסה/שמן וטמפ' מים כניסה/יציאה | I4: הוראות יצרן + נוהל אחזקה מונעת (SLA) | J4: כן — כל הפרמטרים מדווחים ברציפות מבקר הצ'ילר | K4: לא נדרש (קיים) | L4: לא | M4: כן — מלא | N4: SKIP (ברירת מחדל דיגיטלית) | O4: כל הפרמטרים בטווח היצרן ברציפות ב-24 השעות האחרונות | P4: חריגה חד-פעמית קלה מהטווח (התרעת סף צהוב) | Q4: חריגה חוזרת/משמעותית, או אובדן תקשורת עם הבקר מעל שעה | R4: 15 | S4: =G4*R4/60 | T4: 20 | U4: 12 | V4: =T4*U4/60 | W4: =S4-V4 | X4: =IFERROR(W4/S4,0) | Y4: הבדיקה הופכת מ'משימה יומית' ל-Dashboard חי + טיפול ב-20 חריגות בשנה בלבד
A5: 2 | B5: מערכות מים | C5: חדר משאבות מים | D5: בדיקת חדר משאבות מים | E5: יומי | F5: B — נדרש חיישן IoT נוסף | G5: 365 | H5: ניקיון, תאורה, רעשים חריגים ותקינות לוחות חשמל (ג'וקי/ספרינקלרים/הגברת לחץ) | I5: נוהל פנימי / SLA אחזקה | J5: חלקי — סטטוס הפעלה/תקלה בלוחות בד"כ מדווח, רעש/ניקיון לא | K5: כן — חיישן רעד/זרם על המשאבות | L5: לא | M5: כן — ברובו | N5: SKIP/INSPECT | O5: אין אזעקת לוח חשמל ואין חריגת רעד/זרם מהחיישנים | P5: ביקור פיזי שבועי קבוע (ניקיון/ריח/מפגעים) + מיידי בהתרעה | Q5: אזעקת לוח חשמל, נזילה או חריגת רעד | R5: 10 | S5: =G5*R5/60 | T5: 52 | U5: 10 | V5: =T5*U5/60 | W5: =S5-V5 | X5: =IFERROR(W5/S5,0) | Y5: מ-365 סיורים לשנה ל-52 (שבועי) + טיפול נקודתי בחריגות
A6: 3 | B6: מערכות מים | C6: חדר משאבות מי שתייה | D6: בדיקת חדר משאבות מי שתייה | E6: יומי | F6: B — נדרש חיישן IoT נוסף | G6: 365 | H6: תאורה, ניקיון, רעשים חריגים וגלישת מאגר מים תחתון | I6: נוהל פנימי / תקנות איכות מי שתייה (עקיף) | J6: חלקי — מפלס מאגר לרוב מנוטר, רעש/גלישה לא תמיד | K6: כן — חיישן מפלס/גלישה | L6: לא | M6: כן — ברובו | N6: SKIP/INSPECT | O6: מפלס המאגר תקין ואין התרעת גלישה | P6: ביקור פיזי שבועי + מיידי בהתרעת מפלס | Q6: התרעת גלישה/מפלס קיצוני | R6: 8 | S6: =G6*R6/60 | T6: 52 | U6: 8 | V6: =T6*U6/60 | W6: =S6-V6 | X6: =IFERROR(W6/S6,0)
A7: 4 | B7: מערכות מים | C7: מאגר מים עליון | D7: בדיקת מאגר מים עליון | E7: יומי | F7: A — נתון קיים בבקר (אוטומציה מיידית) | G7: 365 | H7: רעשים/רעידות, נזילות, לחץ סניקה (BAR) וגובה מפלס מים | I7: נוהל פנימי / SLA | J7: כן — מפלס ולחץ סניקה ניתנים לניטור רציף בחיישן קיים/זול | K7: לא נדרש (או חיישן מפלס זול אם חסר) | L7: לא | M7: כן — מלא | N7: SKIP (ברירת מחדל דיגיטלית) | O7: מפלס ולחץ בטווח התקין ברציפות | P7: סטייה קלה ממפלס יעד | Q7: מפלס קיצוני / אובדן לחץ / נזילה מדווחת | R7: 8 | S7: =G7*R7/60 | T7: 15 | U7: 10 | V7: =T7*U7/60 | W7: =S7-V7 | X7: =IFERROR(W7/S7,0)
A8: 5 | B8: מערכות מים | C8: משאבות סחרור מים | D8: בדיקת משאבות סחרור מים | E8: יומי | F8: A — נתון קיים בבקר (אוטומציה מיידית) | G8: 365 | H8: רעשים/רעידות, נזילות, לחצי יניקה/סניקה והפרש לחץ על הפילטר | I8: הוראות יצרן / SLA | J8: כן — לחצים והפרש לחץ פילטר ניתנים לניטור דיגיטלי | K8: לא נדרש (או חיישן ΔP זול אם חסר) | L8: לא | M8: כן — מלא | N8: SKIP (ברירת מחדל דיגיטלית) | O8: לחצים והפרש הלחץ על הפילטר בטווח היעד | P8: הפרש לחץ מתקרב לסף החלפת פילטר | Q8: הפרש לחץ מעבר לסף / אובדן לחץ סניקה | R8: 8 | S8: =G8*R8/60 | T8: 20 | U8: 10 | V8: =T8*U8/60 | W8: =S8-V8 | X8: =IFERROR(W8/S8,0)
A9: 6 | B9: מערכת חשמל | C9: חדר חשמל ראשי | D9: בדיקת חדר חשמל ראשי | E9: יומי | F9: B — נדרש חיישן IoT נוסף | G9: 365 | H9: חום חריג בחדר, מנתקים שקפצו, ריח שרוף ותקינות מיזוג החדר | I9: הוראות יצרן / בטיחות אש (מניעת התחממות יתר) | J9: חלקי — חלק מהלוחות המודרניים מדווחים טמפ'/סטטוס מפסק, ריח שרוף לא | K9: כן — חיישן טמפ'/עשן בחדר החשמל | L9: לא (אך רגיש בטיחותית — ראה הערה) | M9: כן — ברובו, בכפוף להתקנת חיישן עשן/טמפ' ייעודי | N9: SKIP/INSPECT | O9: טמפ' תקינה ואין אזעקת עשן/מנתק | P9: סיור פיזי שבועי + מיידי בהתרעה | Q9: חריגת טמפ'/עשן/מנתק שקפץ | R9: 6 | S9: =G9*R9/60 | T9: 52 | U9: 8 | V9: =T9*U9/60 | W9: =S9-V9 | X9: =IFERROR(W9/S9,0) | Y9: למרות האוטומציה — מומלץ לשמר סיור פיזי תדיר יחסית בשל רגישות בטיחותית (סיכון שריפה)
A10: 7 | B10: מערכות מים | C10: לוח חשמל משאבות ניקוז | D10: בדיקת לוח חשמל משאבות ניקוז | E10: יומי | F10: A — נתון קיים בבקר (אוטומציה מיידית) | G10: 365 | H10: ניקוזים בכניסה לחניון ורעשים מלוח החשמל | I10: נוהל פנימי | J10: כן — לרוב יש התרעת תקלה/הצפה בלוח | K10: לא נדרש (קיים) | L10: לא | M10: כן — מלא | N10: SKIP (ברירת מחדל דיגיטלית) | O10: אין התרעת תקלה/הצפה בלוח | P10: ביקור פיזי שבועי | Q10: התרעת תקלה/הצפה | R10: 5 | S10: =G10*R10/60 | T10: 52 | U10: 5 | V10: =T10*U10/60 | W10: =S10-V10 | X10: =IFERROR(W10/S10,0)
A11: 8 | B11: מערכת חשמל | C11: אל-פסק (UPS) | D11: בדיקת אל פסק | E11: תלת חודשית | F11: A — נתון קיים בבקר (אוטומציה מיידית) | G11: 4 | H11: ניקיון החדר, מתחי/זרמי כניסה ויציאה ותדירות — נמדדים ידנית מהמסך | I11: הוראות יצרן / המשכיות תפעולית קריטית | J11: כן — תוכנת ניהול ה-UPS מדווחת את כל הפרמטרים הללו ברציפות | K11: לא נדרש (קיים) | L11: לא | M11: כן — מלא לפרמטרים החשמליים, ניקיון פיזי נשאר | N11: SKIP/INSPECT | O11: כל הפרמטרים בטווח ברציפות (ניטור תוכנת UPS) | P11: ביקור פיזי לניקיון/הזעת סוללות אחת לרבעון (ללא תלות בסטטוס) | Q11: התרעת UPS (עומס/סוללה/מעקף) | R11: 20 | S11: =G11*R11/60 | T11: 4 | U11: 10 | V11: =T11*U11/60 | W11: =S11-V11 | X11: =IFERROR(W11/S11,0) | Y11: הזמן פר-ביקור קטן כי הבדיקה ממוקדת בניקיון בלבד; הפרמטרים החשמליים נצפים מרחוק
A12: 9 | B12: מערכת חשמל | C12: שנאים | D12: בדיקת שנאים | E12: שבועית | F12: B — נדרש חיישן IoT נוסף | G12: 52 | H12: זמזומים, טמפ' (מעל 95° לא תקין), תקינות ונטות/מפוחים וציוד בטיחות נלווה | I12: הוראות יצרן / חוק החשמל (עקיף) | J12: חלקי — טמפ' שנאי מודרני מדווחת לרוב לבקר, זמזום/ציוד בטיחות לא | K12: כן — חיישן טמפ' שנאי אם חסר | L12: לא | M12: כן — חלקי | N12: SKIP/INSPECT | O12: טמפ' בטווח התקין ברציפות | P12: ביקור פיזי חודשי קבוע + מיידי בחריגת טמפ' | Q12: טמפ' מעל 95° / זמזום חריג מדווח | R12: 15 | S12: =G12*R12/60 | T12: 12 | U12: 15 | V12: =T12*U12/60 | W12: =S12-V12 | X12: =IFERROR(W12/S12,0)
A13: 10 | B13: גנרטורים | C13: גנרטור דיזל — בריקם | D13: בדיקת גנרטור בריקם | E13: שבועית | F13: A — נתון קיים בבקר (אוטומציה מיידית) | G13: 52 | H13: ניתוק מתנע, מתח 400V, תדירות 50Hz, לחץ שמן, טמפ' מי מנוע, רעשים וטעינת מצבר | I13: הוראות יצרן + ביטוח (מוכנות חירום/גיבוי חשמל) | J13: כן — רוב בקרי הגנרטור המודרניים (DSE וכד') מדווחים את כל אלה | K13: לא נדרש (קיים) | L13: לא (אך יש דרישת ביטוח/SLA לתיעוד הפעלה תקופתית) | M13: כן — קריאת הנתונים; ההפעלה עצמה (ריצה בפועל) נשארת | N13: INSPECT (מדורג) | O13: לא רלוונטי — יש חובה תיעודית להרצה תקופתית | P13: ברירת מחדל: הרצה שבועית + קריאת נתונים מהבקר (זמן קצר יותר, ללא רישום ידני) | Q13: אי-עמידה בטווח מתח/תדירות/לחץ/טמפ' בהרצה | R13: 20 | S13: =G13*R13/60 | T13: 52 | U13: 12 | V13: =T13*U13/60 | W13: =S13-V13 | X13: =IFERROR(W13/S13,0) | Y13: ההרצה הפיזית נשמרת (חובת מוכנות חירום) אך הרישום הידני מוחלף בקריאה מהבקר — חיסכון בזמן לא בתדירות
A14: 11 | B14: מיזוג אוויר | C14: צ'ילר | D14: בדיקת צ'ילרים | E14: שבועית | F14: B — נדרש חיישן IoT נוסף | G14: 52 | H14: הקשבה לרעשים חריגים, כתמי שמן/מים, ניקוי מסננים ותקינות בידוד | I14: הוראות יצרן / SLA אחזקה | J14: לא — רעש/דליפה/בידוד אינם נמדדים כיום | K14: כן — חיישן רטט/אקוסטי + חיישן דליפת נוזלים | L14: לא | M14: חלקי | N14: INSPECT (מדורג) | O14: אין התרעת רטט/דליפה וצריכת האנרגיה תקינה | P14: ביקור פיזי חודשי קבוע (ניקוי מסננים) + מיידי בהתרעת חיישן | Q14: התרעת רטט/דליפה מתמשכת או ירידת ביצועים | R14: 25 | S14: =G14*R14/60 | T14: 12 | U14: 25 | V14: =T14*U14/60 | W14: =S14-V14 | X14: =IFERROR(W14/S14,0) | Y14: מ-52 ביקורים לשנה ל-12, בתוספת מקרי חריגה
A15: 12 | B15: מיזוג אוויר | C15: יחידת טיפול באוויר (יט"א) | D15: בדיקת יט"אות | E15: שבועית | F15: B — נדרש חיישן IoT נוסף | G15: 52 | H15: בדיקה ויזואלית לרעשים/רעידות והפרש טמפ' אוויר ביציאה מהמזגן | I15: הוראות יצרן | J15: חלקי — הפרש טמפ' ניתן לניטור אם קיים חיישן ΔT, רעש/רעידות לא | K15: כן — חיישן הפרש טמפ'/לחץ על היחידה | L15: לא | M15: כן — ברובו | N15: SKIP/INSPECT | O15: הפרש הטמפ' בטווח היעד ואין אזעקת יחידה | P15: ביקור פיזי חודשי + מיידי בחריגה | Q15: הפרש טמפ' מחוץ לטווח / אזעקת מנוע-רצועה | R15: 20 | S15: =G15*R15/60 | T15: 12 | U15: 20 | V15: =T15*U15/60 | W15: =S15-V15 | X15: =IFERROR(W15/S15,0)
A16: 13 | B16: מיזוג אוויר | C16: VRF — יחידות פנימיות/חיצוניות | D16: בדיקת מערכת מיזוג אוויר VRF | E16: תלת חודשי | F16: A — נתון קיים בבקר (אוטומציה מיידית) | G16: 4 | H16: בדיקה ויזואלית לנזק מכני/בידוד/קורוזיה, רעשים, ניקוזים ובקרת מערכת | I16: הוראות יצרן | J16: כן — מרכזת VRF מדווחת קודי תקלה ואזהרה | K16: לא נדרש (קיים) | L16: לא | M16: כן — ברובו | N16: SKIP/INSPECT | O16: אין קודי תקלה/אזהרה מהמרכזת וצריכת אנרגיה תקינה | P16: ביקור פיזי חצי-שנתי (ויזואלי/ניקוזים) + מיידי בקוד אזהרה | Q16: קוד תקלה קריטי מהמרכזת | R16: 40 | S16: =G16*R16/60 | T16: 2 | U16: 40 | V16: =T16*U16/60 | W16: =S16-V16 | X16: =IFERROR(W16/S16,0)
A17: 14 | B17: מיזוג אוויר | C17: מפוח נחשון | D17: בדיקת מפוח נחשון | E17: תלת חודשי | F17: C — רגולציה/ביטוח/בטיחות (לא ניתן לביטול) | G17: 4 | H17: ניקוי מגש ניקוז ובדיקת נזילות, פתיחה/סגירת ברזים והחלפת מילוי מסנן | I17: הוראות יצרן | J17: לא — פעולות שירות/ניקוי פיזיות במהותן | K17: כן — חיישן נזילה במגש הניקוז יכול להתריע מוקדם | L17: לא (אך זו בעיקרה עבודת שירות ולא רק 'בדיקה') | M17: חלקי | N17: KEEP (עם הוספת חיישן התרעה) | O17: לא רלוונטי — נדרשת עבודת אחזקה פיזית (ניקוי/החלפת מסנן) | P17: לא רלוונטי — ראה KEEP | Q17: חיישן נזילה מתריע → תיקון מיידי בין המחזורים | R17: 25 | S17: =G17*R17/60 | T17: 4 | U17: 20 | V17: =T17*U17/60 | W17: =S17-V17 | X17: =IFERROR(W17/S17,0) | Y17: החיסכון כאן קטן ומגיע מייעול משך הביקור, לא מביטול — דוגמה לכך שלא כל משימה ניתנת ל-SKIP
A18: 15 | B18: מערכות מים | C18: משאבות מים | D18: בדיקת משאבות מים | E18: שבועי | F18: B — נדרש חיישן IoT נוסף | G18: 52 | H18: קריאת לחצי יניקה/סניקה, הקשבה לרעידות/רעשים ובדיקת נזילות | I18: הוראות יצרן / SLA | J18: כן — לחצים ניתנים לניטור דיגיטלי; רעש/רעד דורש חיישן ייעודי | K18: כן — חיישן רטט למשאבה | L18: לא | M18: כן — ברובו | N18: SKIP/INSPECT | O18: לחצים בטווח היעד ואין התרעת רטט | P18: ביקור פיזי חודשי + מיידי בהתרעה | Q18: התרעת רטט/אובדן לחץ | R18: 12 | S18: =G18*R18/60 | T18: 12 | U18: 12 | V18: =T18*U18/60 | W18: =S18-V18 | X18: =IFERROR(W18/S18,0)
A19: 16 | B19: מערכות מים | C19: מגדלי קירור | D19: בדיקת מגדלי קירור | E19: יומי | F19: B — נדרש חיישן IoT נוסף | G19: 365 | H19: רעשים/רעידות, נזילות, מוליכות (מיקרוסימנס), קריאת מונה מים, מפלס חומרי טיפול וטיימרים | I19: הוראות יצרן / SLA אנרגיה | J19: כן — מוליכות, מפלס חומרים וספירת שעות ניתנים לניטור דיגיטלי במגדלים מודרניים | K19: כן, אם המגדל ישן — חיישן מוליכות/מפלס | L19: לא | M19: כן — מלא לפרמטרי המים/כימיה | N19: SKIP (ברירת מחדל דיגיטלית) | O19: מוליכות ומפלסי חומרי הטיפול בטווח היעד | P19: חריגה קלה במוליכות / התקרבות לסף מפלס | Q19: חריגת מוליכות משמעותית / אזל מלאי חומר טיפול | R19: 15 | S19: =G19*R19/60 | T19: 25 | U19: 12 | V19: =T19*U19/60 | W19: =S19-V19 | X19: =IFERROR(W19/S19,0) | Y19: בדיקת רעשים/רעידות פיזית ממשיכה בסבב השבועי הנפרד (ר' שורה הבאה — קטגוריה C, לג'יונלה)
A20: 17 | B20: מערכת חשמל | C20: לוחות חשמל מתח נמוך | D20: בדיקת לוחות חשמל | E20: חצי שנתית | F20: B — נדרש חיישן IoT נוסף | G20: 2 | H20: פעולת נורות סימון/אזעקה, רעשים, שילוט, מדידת זרמי פעולה של מנועים וכיול מדי זרם/מתח | I20: הוראות יצרן / חוק החשמל (עקיף — לא תחליף לבדיקת בודק מוסמך) | J20: חלקי — זרם/מתח לעומסים מרכזיים מדווח בלוחות עם מוני אנרגיה, לא בכל הלוחות | K20: כן — מצלמת תרמוגרפיה/חיישן זרם להתקנה קבועה בלוחות קריטיים | L20: לא (הבדיקה הפנימית עצמה; קיימת בנפרד חובת בודק חשמל מוסמך – ר' קטגוריה KEEP) | M20: חלקי | N20: INSPECT (מדורג) | O20: לא רלוונטי ברמה שנתית-חצי — נשמרת תדירות הבסיס | P20: ברירת מחדל: ביקור חצי-שנתי, מקוצר אם אין חריגת זרם/תרמוגרפיה מתמשכת | Q20: חריגת זרם/טמפרטורה בין הביקורים → קריאה מיידית | R20: 45 | S20: =G20*R20/60 | T20: 2 | U20: 30 | V20: =T20*U20/60 | W20: =S20-V20 | X20: =IFERROR(W20/S20,0) | Y20: חיישני תרמוגרפיה קבועים מקצרים את זמן הביקור אך לא מבטלים אותו
A21: 18 | B21: מערכות מים | C21: מגדלי קירור | D21: בדיקת מגדלי קירור (טיפול כימי/לגיונלה) | E21: שבועי | F21: C — רגולציה/ביטוח/בטיחות (לא ניתן לביטול) | G21: 52 | H21: כיוונון מצופים, הקשבה לרעשים בצירי מפוחים/מיסבים, בדיקת כלורידים (עד 1500) והזרמת ביוציד נגד אצות/לגיונלה | I21: תקנות בריאות הציבור למניעת לגיונלה במגדלי קירור + הוראות יצרן | J21: לא — טיפול כימי ובקרת לגיונלה מחייבים דגימה/פעולה פיזית | K21: לא רלוונטי כתחליף — ניתן להוסיף ניטור מוליכות/כלור רציף כתמיכה בלבד | L21: כן — מחייב עפ"י תקנות בריאות הציבור | M21: לא | N21: KEEP | O21: אסור — סיכון בריאותי (לגיונלה) הופך זאת לבדיקה שלא ניתן לדלג עליה | P21: לא רלוונטי — ראה KEEP | Q21: חריגת כלורידים/מוליכות → קריאה לחברת טיפול כימי מיידית | R21: 15 | S21: =G21*R21/60 | T21: 52 | U21: 15 | V21: =T21*U21/60 | W21: =S21-V21 | X21: =IFERROR(W21/S21,0) | Y21: דוגמה מרכזית: אין קיצור תדירות למרות שקיימת טכנולוגיית ניטור, כי מקור החובה הוא בריאותי-רגולטורי
A22: 19 | B22: כיבוי אש | C22: מטפה כיבוי אש | D22: בדיקת מטפה | E22: שנתי | F22: C — רגולציה/ביטוח/בטיחות (לא ניתן לביטול) | G22: 1 | H22: בדיקה ויזואלית מקיפה (מד לחץ, שיתוך, תבריג, אטמים, ידית, גלגלים, שסתום) — כ-40 סעיפי בדיקה לכל מטפה | I22: ת"י 1220 (מטפים ניידים לכיבוי אש) — בדיקה תקופתית מחייבת בדין | J22: לא — בדיקה פיזית/מכנית בהגדרה | K22: לא רלוונטי כתחליף | L22: כן — מחייב עפ"י תקן ולעיתים דורש גם בודק מוסמך חיצוני | M22: לא | N22: KEEP | O22: אסור — דרישת תקן מחייבת ללא תלות בטכנולוגיה קיימת | P22: לא רלוונטי — ראה KEEP | Q22: ליקוי שנמצא → החלפה/טיפול מיידי ותיוק באישורי בטיחות | R22: 8 | S22: =G22*R22/60 | T22: 1 | U22: 8 | V22: =T22*U22/60 | W22: =S22-V22 | X22: =IFERROR(W22/S22,0) | Y22: חיסכון = 0 בכוונה — דוגמת 'שער' להראות שהמנוע לא ממליץ SKIP כשיש חובת תקן מפורשת
A23: 20 | B23: כיבוי אש | C23: עמדת כיבוי אש | D23: בדיקת עמדות כיבוי אש | E23: חצי שנתית | F23: C — רגולציה/ביטוח/בטיחות (לא ניתן לביטול) | G23: 2 | H23: בדיקת מלאי (זרנוקים, מזנקים, גלגלון, מטף), תקינות מד לחץ ונזילות בצנרת | I23: תקנות/תקן כיבוי אש (עמדות כיבוי) + דרישת רשות כבאות והצלה | J23: לא — בדיקת מלאי/נזילות פיזית | K23: לא רלוונטי כתחליף | L23: כן | M23: לא | N23: KEEP | O23: אסור — דרישה רגולטורית מחייבת | P23: לא רלוונטי — ראה KEEP | Q23: חוסר במלאי/נזילות → השלמה/תיקון מיידי | R23: 20 | S23: =G23*R23/60 | T23: 2 | U23: 20 | V23: =T23*U23/60 | W23: =S23-V23 | X23: =IFERROR(W23/S23,0)
A24: 21 | B24: כיבוי אש | C24: משאבת כיבוי אש דיזל | D24: בדיקת משאבת כיבוי אש דיזל | E24: חצי שנתית | F24: C — רגולציה/ביטוח/בטיחות (לא ניתן לביטול) | G24: 2 | H24: בדיקת מצבר, דלק, מפלס מים, הפעלת TEST ורישום חום/לחצים בזמן ריצה | I24: תקן/רגולציית כיבוי אש למשאבות (מקביל ל-NFPA20) + דרישת ביטוח מפורשת | J24: חלקי — הרצה עצמה וקריאת נתונים בזמן אמת ניתנים לתיעוד דיגיטלי, אך ההפעלה הפיזית וההפעלה הידנית נדרשות | K24: לא רלוונטי כתחליף לחובה עצמה | L24: כן — מערכת בטיחות חיים קריטית + דרישת מבטח | M24: לא (רק תיעוד הנתונים ניתן לדיגיטציה) | N24: KEEP | O24: אסור — מערכת כיבוי אש קריטית ודרישת ביטוח מפורשת | P24: לא רלוונטי — ראה KEEP | Q24: כשל בהתנעה/חריגת פרמטר → קריאת שירות דחופה + דיווח למבטח | R24: 30 | S24: =G24*R24/60 | T24: 2 | U24: 25 | V24: =T24*U24/60 | W24: =S24-V24 | X24: =IFERROR(W24/S24,0) | Y24: חיסכון קטן בזמן הרישום בלבד (מעבר לטופס דיגיטלי), לא בתדירות ההפעלה
A25: 22 | B25: כיבוי אש | C25: ספרינקלרים ומשאבות כיבוי אש | D25: בדיקת ספרינקלרים | E25: שבועית | F25: C — רגולציה/ביטוח/בטיחות (לא ניתן לביטול) | G25: 52 | H25: הפעלת משאבת דיזל וחשמלית ל-10 דקות, בדיקת דלק/מצברים/נתיכים ומפלס מאגר מי כיבוי | I25: תקן כיבוי אש למערכות ספרינקלרים (מקביל ל-NFPA25) — בדיקה שבועית מחייבת | J25: חלקי — פרמטרים חשמליים/לחץ ניתנים לתיעוד דיגיטלי, אך ההפעלה הפיזית מחויבת | K25: לא רלוונטי כתחליף לחובה | L25: כן | M25: לא (רק תיעוד) | N25: KEEP | O25: אסור — דרישת תקן שבועית מפורשת למערכת כיבוי אש | P25: לא רלוונטי — ראה KEEP | Q25: כשל הפעלה/מפלס נמוך → קריאת שירות דחופה | R25: 35 | S25: =G25*R25/60 | T25: 52 | U25: 30 | V25: =T25*U25/60 | W25: =S25-V25 | X25: =IFERROR(W25/S25,0)
A26: 23 | B26: כיבוי אש | C26: חדר משאבות ספרינקלרים | D26: בדיקת חדר משאבות ספרינקלרים | E26: יומי | F26: C — רגולציה/ביטוח/בטיחות (לא ניתן לביטול) | G26: 365 | H26: בדיקה ויזואלית, נזילות, תקינות לוחות חשמל, גלישת מאגר וניקיון החדר | I26: תקן/רגולציית כיבוי אש (בדיקה יומית ויזואלית) — מערכת בטיחות חיים | J26: חלקי — סטטוס לוחות ומפלס מאגר ניתנים לניטור, נזילה/ניקיון פיזי לא | K26: כן — חיישן נזילה/מפלס כתמיכה (לא כתחליף לחובה) | L26: כן — בדיקה ויזואלית יומית נדרשת עבור מערכת בטיחות חיים | M26: לא (רק תמיכה בהתרעה מוקדמת) | N26: KEEP | O26: אסור — מערכת כיבוי אש קריטית, נדרשת בדיקה ויזואלית יומית | P26: לא רלוונטי — ראה KEEP | Q26: נזילה/תקלת לוח/גלישה → קריאת שירות מיידית | R26: 8 | S26: =G26*R26/60 | T26: 365 | U26: 6 | V26: =T26*U26/60 | W26: =S26-V26 | X26: =IFERROR(W26/S26,0) | Y26: חיסכון קטן — רק בייעול משך הסיור (צ'ק-ליסט דיגיטלי בטלפון), לא בתדירות
A27: 24 | B27: גילוי אש | C27: רכזת גילוי אש ועשן | D27: בדיקת רכזת גילוי אש ועשן | E27: חצי שנתי | F27: C — רגולציה/ביטוח/בטיחות (לא ניתן לביטול) | G27: 2 | H27: בדיקת כרטיסים/נוריות/לחצנים, מצברים, גלאים (החלפה יזומה לפי יצרן) ותפקוד בחירום — ע"י חברה מוסמכת | I27: תקן גילוי אש ועשן (מקביל ל-ת"י 1220 חלק גילוי) — מחייב בודק/חברה מוסמכת | J27: חלקי — סטטוס תקלות שוטף מדווח, אך הבדיקה התקופתית המלאה מחייבת גורם מוסמך | K27: לא רלוונטי כתחליף לבדיקה המוסמכת | L27: כן — בדיקה ע"י חברה מוסמכת מחייבת עפ"י תקן | M27: לא | N27: KEEP | O27: אסור — דרישת תקן מחייבת בדיקת גורם מוסמך | P27: לא רלוונטי — ראה KEEP | Q27: ליקוי שנמצא → תיקון ותיוק אישור בתיק בטיחות | R27: 90 | S27: =G27*R27/60 | T27: 2 | U27: 90 | V27: =T27*U27/60 | W27: =S27-V27 | X27: =IFERROR(W27/S27,0) | Y27: זמן זה הוא בעיקר ליווי/תיאום מול החברה המוסמכת, לא ביצוע עצמי
A28: 25 | B28: מעליות | C28: מעלית נוסעים | D28: בדיקת מעלית נוסעים (טיפול חודשי) | E28: חודשי | F28: C — רגולציה/ביטוח/בטיחות (לא ניתן לביטול) | G28: 12 | H28: בדיקה ויזואלית חדר מכונות, אינטרקום, תאורת חירום בתא, הזמנת חברת אחזקה מוסמכת וקבלת דו"ח טיפול | I28: חוק המעליות ותקנות הבטיחות בעבודה (מעליות) — טיפול חודשי מחייב ע"י מתקין/מוסך מוסמך | J28: חלקי — קודי תקלה ממערכת בקרת מעליות מדווחים לרוב, הטיפול הפיזי לא | K28: לא רלוונטי כתחליף לחובה החוקית | L28: כן — מחייב עפ"י דין (חברה מוסמכת + תיעוד דוח) | M28: לא (רק ניטור קודי תקלה כתמיכה בין ביקורים) | N28: KEEP | O28: אסור — טיפול חודשי מחייב עפ"י חוק המעליות | P28: לא רלוונטי — ראה KEEP | Q28: קוד תקלה בין ביקורים → קריאת שירות מיידית | R28: 20 | S28: =G28*R28/60 | T28: 12 | U28: 15 | V28: =T28*U28/60 | W28: =S28-V28 | X28: =IFERROR(W28/S28,0) | Y28: חיסכון קטן — תיאום/תיוק דוחות בלבד; הביקור המוסמך עצמו לא ניתן לביטול
A29: 26 | B29: אחזקה כללית | C29: גופי תאורת חירום | D29: בדיקת תאורת חירום | E29: חצי שנתי | F29: C — רגולציה/ביטוח/בטיחות (לא ניתן לביטול) | G29: 2 | H29: ניתוק הזנה, פריקה מלאה 30 דק', בדיקת פעולה תקינה 20 דק' והחלפת סוללה/גוף בעת הצורך | I29: ת"י 1220 חלק תאורת חירום / דרישות רשות כבאות והצלה | J29: לא — בדיקת פריקה בפועל היא בדיקה פיזית בהגדרה (אין תחליף מרחוק לבדיקת התרוקנות סוללה בפועל בגוף פשוט) | K29: חלקי — גופי תאורת חירום 'חכמים' עם דיווח עצמי קיימים בשוק ומייתרים חלק מהבדיקה הידנית | L29: כן | M29: חלקי — רק אם משדרגים לגופים חכמים | N29: KEEP (עם שדרוג הדרגתי לגופים חכמים כמסלול עתידי) | O29: אסור כברירת מחדל — אלא אם כל הגופים משודרגים לתאורת חירום עם דיווח עצמי (self-test) | P29: לא רלוונטי — ראה KEEP | Q29: גוף לא עומד ב-20 דק' פעולה → החלפת סוללה/גוף | R29: 120 | S29: =G29*R29/60 | T29: 2 | U29: 120 | V29: =T29*U29/60 | W29: =S29-V29 | X29: =IFERROR(W29/S29,0) | Y29: הזדמנות השקעה: מעבר לגופי self-test חכמים יכול להעביר שורה זו לקטגוריית SKIP בעתיד
A30: 27 | B30: אחזקה כללית | C30: דחסנית אשפה | D30: בדיקת דחסנית אשפה | E30: שבועי | F30: D — מבוסס תפוסה/ביקוש (Demand-Based) | G30: 52 | H30: גירוז, שימון, חיזוק ברגים, ניקוי, בדיקת נזילות/רעשים ובדיקת קיבולת המכל | I30: הוראות יצרן / נוהל פנימי | J30: לא — אך ניתן לצייד בחיישן מפלס מילוי | K30: כן — חיישן מפלס מילוי (Fill-level) בדחסנית | L30: לא | M30: כן — למעבר לתחזוקה מבוססת מילוי בפועל, לא לוח זמנים קבוע | N30: ACT (מבוסס תפוסה, לא לוח זמנים) | O30: מפלס המילוי מתחת לסף ואין התרעת נזילה/רעש | P30: ביקור פיזי חודשי קבוע (גירוז/שימון מונע) גם ללא התרעה | Q30: מפלס המילוי מעל סף / התרעת רעש-נזילה — פינוי/טיפול מיידי | R30: 25 | S30: =G30*R30/60 | T30: 12 | U30: 25 | V30: =T30*U30/60 | W30: =S30-V30 | X30: =IFERROR(W30/S30,0) | Y30: גם תדירות הפינוי עצמו יכולה לרדת ממדיניות קבועה למדיניות מבוססת-מילוי
A31: 28 | B31: אחזקה כללית | C31: דוחס קרטונים | D31: בדיקת דוחס קרטונים | E31: שבועי | F31: D — מבוסס תפוסה/ביקוש (Demand-Based) | G31: 52 | H31: בדיקה ויזואלית, תקינות עצירת חירום, מנעולי בטיחות ותקינות מנגנון הפליטה | I31: הוראות יצרן / בטיחות מכונות | J31: לא — אך ניתן לצייד בחיישן מילוי + ניטור מרחוק של עצירת החירום | K31: כן — חיישן מילוי + ניטור סטטוס עצירת חירום | L31: לא (למעט מרכיב הבטיחות — עצירת חירום נבדקת בתדירות קבועה) | M31: כן — ברובו למעט בדיקת בטיחות תקופתית | N31: INSPECT (מדורג, מבוסס תפוסה) | O31: אין התרעת מילוי/תקלה | P31: ברירת מחדל: ביקור חודשי (כולל בדיקת בטיחות עצירת חירום) + לפי התרעת מילוי | Q31: התרעת מילוי מלא / כשל בבדיקת בטיחות | R31: 15 | S31: =G31*R31/60 | T31: 12 | U31: 15 | V31: =T31*U31/60 | W31: =S31-V31 | X31: =IFERROR(W31/S31,0) | Y31: בדיקת עצירת החירום עצמה לא מבוטלת — נשמרת כבדיקת בטיחות תקופתית קבועה
A32: 29 | B32: אחזקה כללית | C32: פיר אשפה | D32: בדיקת פיר אשפה | E32: שבועי | F32: B — נדרש חיישן IoT נוסף | G32: 52 | H32: בדיקת ניקיון פיר האשפה | I32: נוהל פנימי / תברואה | J32: לא — אך ניתן לצייד בחיישן ריח/מילוי | K32: כן — חיישן ריח/מילוי בתא האיסוף | L32: לא | M32: כן — מלא | N32: ACT (מבוסס חיישן ריח/מילוי) | O32: אין התרעת ריח/מילוי | P32: ביקור פיזי חודשי כבסיס | Q32: התרעת ריח חריג / מילוי מלא — ניקוי מיידי | R32: 5 | S32: =G32*R32/60 | T32: 12 | U32: 5 | V32: =T32*U32/60 | W32: =S32-V32 | X32: =IFERROR(W32/S32,0)
A33: 30 | B33: אחזקה כללית | C33: קומות משרדים / שטחים ציבוריים | D33: סיור יומי (ניקיון ותחזוקה כללית) | E33: יומי | F33: D — מבוסס תפוסה/ביקוש (Demand-Based) | G33: 365 | H33: ניקיון כללי, ריקון פחים, תקינות תאורה/דלתות ותקינות מפיצי ריח | I33: נוהל פנימי / רמת שירות (SLA) לדיירים | J33: לא — אך תפוסה בפועל ניתנת למדידה (בקרת כניסה/מצלמות/חיישני נוכחות) | K33: כן — חיישני תפוסה/ספירת מבקרים לכל קומה, מונים חכמים על פחי אשפה | L33: לא | M33: כן — מעבר למודל Demand-Based Cleaning | N33: ACT (מבוסס תפוסה בפועל, לא סבב קבוע לכל הקומות) | O33: קומה עם תפוסה נמוכה ופחים לא מלאים מאז הסבב הקודם | P33: ביקור מהיר לקומות בתפוסה בינונית | Q33: תפוסה גבוהה / פח מלא / התרעת ריח — ניקיון מיידי באותה קומה | R33: 30 | S33: =G33*R33/60 | T33: 200 | U33: 25 | V33: =T33*U33/60 | W33: =S33-V33 | X33: =IFERROR(W33/S33,0) | Y33: הליבה של 'Demand-Based Cleaning' מהמסמך — הפחתה משוערת ~30-40% בסבבים כוללת, לא ביטול מוחלט
A34: 31 | B34: אחזקה כללית | C34: חניון | D34: סיור יומי - חניון | E34: יומי | F34: B — נדרש חיישן IoT נוסף | G34: 365 | H34: בדיקה ויזואלית, נעילת דלתות, תאורה, נזילות וניקיון | I34: נוהל פנימי | J34: חלקי — תאורה/CO ניתנים לניטור ברוב החניונים המודרניים, נזילות/נעילה לא | K34: כן — חיישן נעילה/גישה + ניצול חיישני CO הקיימים לניטור איכות אוויר | L34: לא | M34: כן — ברובו | N34: SKIP/INSPECT | O34: דלתות נעולות (חיישן), תאורה תקינה, אין התרעת CO | P34: ביקור פיזי שבועי + מיידי בהתרעה | Q34: דלת פרוצה / התרעת CO / נזילה מדווחת | R34: 15 | S34: =G34*R34/60 | T34: 52 | U34: 15 | V34: =T34*U34/60 | W34: =S34-V34 | X34: =IFERROR(W34/S34,0)
A35: 32 | B35: מפוחים | C35: לוח מפוחי חניון | D35: בדיקת לוח מפוחי חניון | E35: יומי | F35: A — נתון קיים בבקר (אוטומציה מיידית) | G35: 365 | H35: רעשים חריגים, ניקיון ובדיקה ויזואלית של נורת תקלה | I35: נוהל פנימי — המפוחים עצמם כבר מופעלים אוטומטית ע"י חיישני CO | J35: כן — נורת תקלה/סטטוס מפוח כבר מדווחת ללוח ולעיתים למרכזת | K35: לא נדרש (קיים — מפוחי חניון כבר מבוססי חיישני CO) | L35: לא | M35: כן — מלא | N35: SKIP (ברירת מחדל דיגיטלית) | O35: אין נורת תקלה / התרעה מהלוח | P35: ביקור פיזי חודשי | Q35: נורת תקלה דולקת / אזעקת CO ללא הפעלת מפוח | R35: 5 | S35: =G35*R35/60 | T35: 12 | U35: 5 | V35: =T35*U35/60 | W35: =S35-V35 | X35: =IFERROR(W35/S35,0) | Y35: דוגמה טובה: המערכת כבר Condition-Based מטבעה (CO-driven) — הבדיקה היומית של הלוח היא זו שמיותרת
A36: 33 | B36: ביטחון | C36: סיורי שטח | D36: סיור ביטחון | E36: יומי | F36: B — נדרש חיישן IoT נוסף | G36: 365 | H36: סיור ברחבי המבנה ואיתור חריגים/חפצים חשודים | I36: נוהל אבטחה של המבנה + דרישות ביטוח/רישיון עסק (בהתאם לסיווג האתר) | J36: חלקי — כיסוי מצלמות/Video Analytics קיים באזורים מסוימים בלבד | K36: כן — Video Analytics + בקרת כניסה בנקודות מפתח (לא מחליף כיסוי מלא) | L36: תלוי — ייתכן ומחייב עפ"י נוהל ביטחון/ביטוח ספציפי לאתר | M36: חלקי — בזהירות רבה | N36: INSPECT (מדורג, בכפוף לאישור מפורש) | O36: אסור להחיל ללא אישור מפורש של גורם הביטחון/הביטוח של המבנה | P36: באזורים מכוסי מצלמות/Video Analytics מלא: תדירות מופחתת; באזורים לא מכוסים: ללא שינוי | Q36: התרעת Video Analytics (חפץ חשוד/פריצה) → סיור מיידי לאזור הספציפי | R36: 15 | S36: =G36*R36/60 | T36: 200 | U36: 15 | V36: =T36*U36/60 | W36: =S36-V36 | X36: =IFERROR(W36/S36,0) | Y36: בהתאם למסמך החזון — תחום רגיש; כל צמצום מותנה מראש באישור דרישות ביטחון/ביטוח/נהלים, לא רק ביכולת הטכנולוגית
A37: 34 | B37: מעליות | C37: חדר מעליות חניון | D37: בדיקת חדר מעליות חניון | E37: יומי | F37: B — נדרש חיישן IoT נוסף | G37: 365 | H37: תאורה, ניקיון, נזילות שמן, פעולת מזגן חדר ורעשים מלוחות חשמל | I37: נוהל פנימי (מעבר לחובת הטיפול החודשי המוסמך שנשמרת בנפרד) | J37: חלקי — קודי תקלה ממערכת בקרת המעלית מדווחים, נזילת שמן/ניקיון לא | K37: כן — חיישן נזילת שמן + ניטור טמפ' חדר | L37: לא (הביקור היומי הפנימי; להבדיל מהטיפול החודשי המוסמך שנותר KEEP) | M37: כן — ברובו | N37: SKIP/INSPECT | O37: אין קוד תקלה, אין התרעת נזילה/טמפ' | P37: ביקור פיזי שבועי + מיידי בהתרעה | Q37: קוד תקלה / נזילת שמן / חריגת טמפ' | R37: 8 | S37: =G37*R37/60 | T37: 52 | U37: 8 | V37: =T37*U37/60 | W37: =S37-V37 | X37: =IFERROR(W37/S37,0)
A38: 35 | B38: מעליות | C38: חדר מעליות נוסעים | D38: בדיקת חדר מעליות נוסעים | E38: יומי | F38: A — נתון קיים בבקר (אוטומציה מיידית) | G38: 365 | H38: ניקיון, תאורה ורעשים חריגים | I38: נוהל פנימי | J38: חלקי — קודי תקלה ממערכת בקרת המעלית מדווחים | K38: לא נדרש נוסף (קיים) | L38: לא | M38: כן — ברובו | N38: SKIP/INSPECT | O38: אין קוד תקלה מהמעלית | P38: ביקור פיזי שבועי + מיידי בהתרעה | Q38: קוד תקלה מדווח | R38: 6 | S38: =G38*R38/60 | T38: 52 | U38: 6 | V38: =T38*U38/60 | W38: =S38-V38 | X38: =IFERROR(W38/S38,0)
A39: 36 | B39: אחזקה כללית | C39: לוח בקרת מבנה (BMS) | D39: בדיקת לוח בקרת מבנה | E39: חודשית | F39: A — נתון קיים בבקר (אוטומציה מיידית) | G39: 12 | H39: ניקיון ושלמות שילוט, קיום דף הוראות, חיזוק מכני ופעולת נורות/מפסקים/לחצנים | I39: נוהל פנימי / הוראות יצרן | J39: כן — זהו הלוח עצמו; רוב הפרמטרים התפעוליים כבר מוצגים בו | K39: לא נדרש | L39: לא | M39: חלקי — הבדיקה הפיזית (שילוט/ניקיון/חיזוק) עדיין נדרשת אך בתדירות נמוכה יותר | N39: INSPECT (מדורג) | O39: אין תקלת חומרה/תצוגה מדווחת | P39: ביקור פיזי רבעוני (במקום חודשי) + מיידי בתקלה מדווחת | Q39: נורית/מסך לא תקינים או תקלת חומרה | R39: 15 | S39: =G39*R39/60 | T39: 4 | U39: 15 | V39: =T39*U39/60 | W39: =S39-V39 | X39: =IFERROR(W39/S39,0)
A40: סה"כ | S40: =SUM(S4:S39) | V40: =SUM(V4:V39) | W40: =SUM(W4:W39) | X40: =IFERROR(W40/S40,0)

Sheet תקציר מנהלים
A1: BUILDING OPERATIONS — תקציר מנהלים (שלב 1: Blueprint)
A2: מבוסס על 36 המשימות הראשונות שנותחו מתוך 230 המשימות בתוכנית האחזקה. נתוני MVP להערכה — לאימות בפיילוט.
A4: מדד | B4: ערך
A5: סה"כ משימות שנותחו בשלב 1 | B5: 36
A6: מתוכן ניתנות למעבר מלא/חלקי לניהול מבוסס-חריגות (SKIP/INSPECT/ACT) | B6: =36-(SUMPRODUCT(--(LEFT('מפת החלטות מאסטר'!N4:N39,4)="KEEP")))
A7: מתוכן חייבות להישאר KEEP (רגולציה / ביטוח / בטיחות חיים) | B7: =SUMPRODUCT(--(LEFT('מפת החלטות מאסטר'!N4:N39,4)="KEEP"))
A8: שעות עבודה בשנה — היום (36 המשימות) | B8: ='מפת החלטות מאסטר'!S40 | C8: שעות
A9: שעות עבודה בשנה — לאחר מעבר לניהול מבוסס-חריגות | B9: ='מפת החלטות מאסטר'!V40 | C9: שעות
A10: חיסכון שעות עבודה לשנה | B10: ='מפת החלטות מאסטר'!W40 | C10: שעות
A11: אחוז חיסכון ממוצע (36 המשימות שנותחו) | B11: ='מפת החלטות מאסטר'!X40
A13: פילוח לפי סיווג אסטרטגי
A14: סיווג | B14: מס' משימות | C14: חיסכון שעות/שנה
A15: A — נתון קיים בבקר (אוטומציה מיידית) | B15: =COUNTIF('מפת החלטות מאסטר'!F4:F39,"A — נתון קיים בבקר (אוטומציה מיידית)") | C15: =SUMIF('מפת החלטות מאסטר'!F4:F39,"A — נתון קיים בבקר (אוטומציה מיידית)",'מפת החלטות מאסטר'!W4:W39)
A16: B — נדרש חיישן IoT נוסף | B16: =COUNTIF('מפת החלטות מאסטר'!F4:F39,"B — נדרש חיישן IoT נוסף") | C16: =SUMIF('מפת החלטות מאסטר'!F4:F39,"B — נדרש חיישן IoT נוסף",'מפת החלטות מאסטר'!W4:W39)
A17: C — רגולציה/ביטוח/בטיחות (לא ניתן לביטול) | B17: =COUNTIF('מפת החלטות מאסטר'!F4:F39,"C — רגולציה/ביטוח/בטיחות (לא ניתן לביטול)") | C17: =SUMIF('מפת החלטות מאסטר'!F4:F39,"C — רגולציה/ביטוח/בטיחות (לא ניתן לביטול)",'מפת החלטות מאסטר'!W4:W39)
A18: D — מבוסס תפוסה/ביקוש (Demand-Based) | B18: =COUNTIF('מפת החלטות מאסטר'!F4:F39,"D — מבוסס תפוסה/ביקוש (Demand-Based)") | C18: =SUMIF('מפת החלטות מאסטר'!F4:F39,"D — מבוסס תפוסה/ביקוש (Demand-Based)",'מפת החלטות מאסטר'!W4:W39)

Sheet מקרא ומתודולוגיה
A1: מקרא ומתודולוגיה — Master Decision Matrix
A3: 1. מטרת המסמך
B4: שלב 1 (Blueprint) בתהליך בניית מנוע ההחלטות התפעוליות: פירוק תוכנית האחזקה המונעת הקיימת (230 משימות, 12 מערכות) וניסוח לוגיקת KEEP / SKIP / INSPECT / ACT לכל משימה, כבסיס לאפיון תוכנה ולשיחה עם מפתח.
A6: 2. ארבע ההחלטות האפשריות
A7: KEEP | B7: המשימה נשארת כפי שהיא, בתדירותה המקורית — כי מקור החובה שלה (תקן/רגולציה/ביטוח/בטיחות חיים) אינו מאפשר החלפה בטכנולוגיה, גם אם הטכנולוגיה קיימת.
A8: SKIP | B8: המשימה מבוטלת כברירת מחדל ומוחלפת בניטור דיגיטלי רציף — מבוצעת פיזית רק כאשר מתקבלת חריגה.
A9: INSPECT | B9: תדירות הביקור הפיזי מופחתת (לא מבוטלת), לרוב משילוב של ניטור דיגיטלי חלקי + הוספת חיישן IoT.
A10: ACT | B10: המשימה עוברת ממודל 'לוח זמנים קבוע' למודל 'מבוסס ביקוש/תפוסה/מילוי' — מבוצעת כשנדרש בפועל, לא לפי יום קבוע מראש.
A12: 3. הסיווג האסטרטגי (A/B/C/D)
A13: A — נתון קיים בבקר | B13: המידע הדרוש להחלטה כבר זמין היום מהבקר/ה-BMS הקיים. פוטנציאל האוטומציה הגבוה והמהיר ביותר — לא דורש השקעת חומרה.
A14: B — נדרש חיישן IoT נוסף | B14: הנתון אינו קיים כיום (למשל רעד, דליפה, הפרש לחץ). נדרשת השקעה נקודתית בחיישן זול לפני שניתן לצמצם ביקורים פיזיים.
A15: C — רגולציה/ביטוח/בטיחות | B15: מקור החובה חיצוני ומחייב (תקן, חוק, דרישת מבטח, בטיחות חיים) — המנוע אינו מציע SKIP גם אם קיימת טכנולוגיה, זהו 'שער' ה-Compliance.
A16: D — מבוסס תפוסה/ביקוש | B16: המשימה קשורה לשימוש בפועל בשטח (ניקיון, פינוי אשפה, סיורים) — עוברת ממודל תדיר קבוע למודל המגיב לנתוני תפוסה/מילוי בפועל.
A18: 4. עיקרון מרכזי: 'יש חיישן' אינו אומר 'אפשר SKIP'
B19: לפני שקובעים החלטת SKIP למשימה, לא מספיק לבדוק "האם יש חיישן על הציוד הזה" — צריך לבדוק ספציפית "האם החיישן הקיים באמת מכסה את סוג הכשל שהבדיקה הפיזית המקורית נועדה לתפוס". לדוגמה: חיישן טמפרטורה וסטטוס מפסקים על לוח חשמל לא בהכרח מזהה נתיך שנשרף במעגל ספציפי, קורוזיה, חיבור רופף או ריח שרוף — אלה כשלים שהבדיקה הפיזית הידנית נועדה לתפוס ושהחיישנים הקיימים אינם מכסים בהכרח.
A20: מסקנה מעשית | B20: כשקיים פער כיסוי כזה, ההחלטה הנכונה היא INSPECT (ביקור פיזי בתדירות מופחתת, ממוקד ספציפית במה שהחיישנים לא רואים) ולא SKIP מלא — עד שמתווסף חיישן ייעודי שסוגר את הפער הספציפי (למשל חיישן זרם/רציפות לכל מעגל בנפרד, לא רק טמפ' כללית של הלוח).
A21: הבחנה חשובה נוספת | B21: יש להבדיל בין שתי שכבות שונות של בדיקה שקל לבלבל ביניהן: (1) בדיקה שנתית ע"י גורם מוסמך חיצוני (למשל בודק חשמל מוסמך) — זו בדרך כלל מוגדרת בחוק/תקנות, ונשארת KEEP ללא תלות בטכנולוגיה. (2) סיור פנימי שוטף של צוות האחזקה (יומי/שבועי) — לרוב אין לו תקן חיצוני שמגדיר תדירות/פרוטוקול מדויק, והוא הצטבר כנוהל/Best Practice. שכבה (2) היא המועמדת הטבעית לצמצום, אך מהסיבה הטכנית שבסעיף הזה (פער כיסוי חיישנים) — לא מהיעדר חובה רגולטורית.
A23: 5. הסבר עמודות מפת ההחלטות
A24: מערכת / ציוד / משימה | B24: כפי שמופיעים בתוכנית האחזקה המקורית (12 לשוניות, 230 משימות) — שומר על שקיפות מלאה מול המקור.
A25: תדירות נוכחית / מופעים לשנה (היום) | B25: התדירות כפי שנקבעה היום בתוכנית האחזקה, מתורגמת למספר מופעים שנתי.
A26: מה נבדק בפועל | B26: תמצית הצ'ק-ליסט המקורי לאותה משימה.
A27: מקור החובה (Compliance) | B27: הסיבה שבגללה המשימה קיימת: תקן ישראלי, חוק, הוראות יצרן, דרישת ביטוח, SLA או נוהל פנימי. זהו הבסיס לכל החלטת KEEP.
A28: נתון קיים בבקר/BMS? | B28: האם המידע הדרוש להערכת מצב המערכת כבר מגיע היום מבקר/רכזת/תוכנת ניהול קיימת.
A29: חיישן IoT נדרש | B29: אם המידע חסר — איזה חיישן זול נדרש כדי להשלים אותו (רטט, דליפה, מילוי, הפרש לחץ וכו').
A30: בדיקה פיזית חובה עפ"י דין/תקן? | B30: דגל Compliance מפורש — אם כן, לא מוצעת החלטת SKIP למשימה, ללא תלות ביכולת הטכנולוגית.
A31: ניתן למעבר לניהול מבוסס חריגות? | B31: הערכה כללית (כן/חלקי/לא) של מידת ההתאמה של המשימה למודל Condition-Based.
A32: החלטת ברירת מחדל | B32: אחת מארבע ההחלטות (KEEP/SKIP/INSPECT/ACT), עם צביעה תואמת.
A33: תנאי SKIP / INSPECT / ACT | B33: הלוגיקה בפועל: מתי המנוע מדלג, מתי הוא שולח לבדיקה מופחתת, ומתי הוא פותח קריאת שירות/פעולה.
A34: זמן ביצוע (דק') / מופעים חזויים / שעות בשנה | B34: הערכות MVP לחישוב חיסכון פוטנציאלי — ראו הנחות עבודה בסעיף 6.
A36: 6. הנחות עבודה ומגבלות (MVP)
A37: • | B37: אומדני 'זמן ביצוע' ו'מופעים חזויים' הם הערכות סבירות של צוות הפיתוח בשלב Blueprint, ולא נתוני אמת נמדדים — מטרתן לבנות מודל חישוב שניתן להזין אליו בהמשך נתוני זמן אמיתיים (למשל ממגדלי הארבעה).
A38: • | B38: כל שורת KEEP מייצגת בכוונה חיסכון אפס או נמוך — זו דוגמה מכוונת לכך שהמנוע אינו ממליץ לבטל משימה רק כי קיימת טכנולוגיה, כאשר מקור החובה חיצוני ומחייב.
A39: • | B39: שורות 'סיור ביטחון' מסומנות באזהרה מפורשת: כל צמצום מותנה באישור מראש של גורם הביטחון/הביטוח של הבניין — לא רק ביכולת הטכנולוגית, בהתאם לעיקרון הזהירות שהוגדר במסמך החזון.
A40: • | B40: המשימות שנבחרו (36 מתוך 230) הן אלה בעלות פוטנציאל ההשפעה הגבוה ביותר (תדירות גבוהה + פוטנציאל אוטומציה) — הרחבה ליתר המשימות היא שלב 2 של התהליך.
A41: • | B41: מקור החובה (Compliance) מבוסס על ידע כללי בתחום התקינה בישראל (ת"י 1220 ודומיו) ואינו מהווה ייעוץ משפטי/הנדסי — יש לאמת מול יועץ בטיחות/חשמל/כיבוי אש מוסמך לפני יישום בפועל.
A43: 7. השלבים הבאים (מתוך מסמך החזון + ממצאי הסיור במגדלי הארבעה)
A44: → | B44: הרחבת המטריצה ליתר 194 המשימות בתוכנית האחזקה (ולתוכנית הניקיון, כשתתקבל).
A45: → | B45: אימות מול נתוני אמת ממגדלי הארבעה — זמני ביצוע בפועל, מפת חיישנים/בקרים קיימת בפועל בכל מגדל.
A46: → | B46: בירור טכני מול G1 הוטלו (מתחזקי מערכת הבקרה, פלטפורמת Trend/IQ-4): קיום ממשק BACnet/OPC או גישת קריאה למסד הנתונים/Trend log.
A47: → | B47: בירור מול Visitt לגבי גישת API/ייצוא להיסטוריית המשימות שכבר קיימת בפועל בבניין — מקור נתוני אמת מהימן לכיול המודל.
...
